<?xml version="1.0" ?>
<sdf version='1.6'>
  <model name='my_robot'>
    <link name='base_footprint'>
      <inertial>
        <pose>2e-06 0 0.074739 0 -0 0</pose>
        <mass>1500.2</mass>
        <inertia>
          <ixx>7.41845</ixx>
          <ixy>-6.19668e-22</ixy>
          <ixz>-0.000312412</ixz>
          <iyy>8.59482</iyy>
          <iyz>0</iyz>
          <izz>4.48214</izz>
        </inertia>
      </inertial>
      <collision name='base_footprint_fixed_joint_lump__base_link_collision'>
        <pose>0 0 0.10525 0 -0 0</pose>
        <geometry>
          <cylinder>
            <length>0.1855</length>
            <radius>0.07</radius>
          </cylinder>
        </geometry>
        <surface>
          <contact>
            <ode/>
          </contact>
          <friction>
            <ode/>
          </friction>
        </surface>
      </collision>
      <collision name='base_footprint_fixed_joint_lump__camera_collision_1'>
        <pose>0.07 0 0.164 1.5708 -0 0</pose>
        <geometry>
          <box>
            <size>0.025 0.025 0.01</size>
          </box>
        </geometry>
        <surface>
          <contact>
            <ode/>
          </contact>
          <friction>
            <ode/>
          </friction>
        </surface>
      </collision>
      <collision name='base_footprint_fixed_joint_lump__front_caster_wheel_link_collision_2'>
        <pose>0.0485 0 0.01267 0 -0 0</pose>
        <geometry>
          <sphere>
            <radius>0.0125</radius>
          </sphere>
        </geometry>
        <surface>
          <contact>
            <ode/>
          </contact>
          <friction>
            <ode/>
          </friction>
        </surface>
      </collision>
      <collision name='base_footprint_fixed_joint_lump__bno055_collision_3'>
        <pose>0 0 0.1885 0 -0 1.5708</pose>
        <geometry>
          <box>
            <size>0.02 0.025 0.0045</size>
          </box>
        </geometry>
      </collision>
      <collision name='base_footprint_fixed_joint_lump__laser_collision_4'>
        <pose>0 0 0.21615 0 -0 0</pose>
        <geometry>
          <cylinder>
            <length>0.0413</length>
            <radius>0.0348</radius>
          </cylinder>
        </geometry>
      </collision>
      <collision name='base_footprint_fixed_joint_lump__rear_caster_wheel_link_collision_5'>
        <pose>-0.0485 0 0.01267 0 -0 0</pose>
        <geometry>
          <sphere>
            <radius>0.0125</radius>
          </sphere>
        </geometry>
        <surface>
          <contact>
            <ode/>
          </contact>
          <friction>
            <ode/>
          </friction>
        </surface>
      </collision>
      <visual name='base_footprint_fixed_joint_lump__base_link_visual'>
        <pose>0 0 0.15 1.5708 -0 1.5708</pose>
        <geometry>
          <mesh>
            <scale>0.001 0.001 0.001</scale>
            <uri>model://meshes/my_robot_base.stl</uri>
          </mesh>
        </geometry>
        <material>
          <script>
            <name>Gazebo/DarkGrey</name>
            <uri>file://media/materials/scripts/gazebo.material</uri>
          </script>
        </material>
      </visual>
      <visual name='base_footprint_fixed_joint_lump__camera_visual_1'>
        <pose>0.07 0 0.164 1.5708 -0 0</pose>
        <geometry>
          <mesh>
            <scale>0.001 0.001 0.001</scale>
            <uri>model://meshes/cam_v2_1_v1.stl</uri>
          </mesh>
        </geometry>
        <material>
          <script>
            <name>Gazebo/Red</name>
            <uri>file://media/materials/scripts/gazebo.material</uri>
          </script>
        </material>
      </visual>
      <visual name='base_footprint_fixed_joint_lump__front_caster_wheel_link_visual_2'>
        <pose>0.0485 0.0065 0.01267 0 0 -1.5708</pose>
        <geometry>
          <mesh>
            <scale>0.001 0.001 0.001</scale>
            <uri>model://meshes/caster_wheel.stl</uri>
          </mesh>
        </geometry>
        <material>
          <script>
            <name>Gazebo/FlatBlack</name>
            <uri>file://media/materials/scripts/gazebo.material</uri>
          </script>
        </material>
      </visual>
      <visual name='base_footprint_fixed_joint_lump__bno055_visual_3'>
        <pose>0 0 0.18625 0 -0 0</pose>
        <geometry>
          <mesh>
            <scale>0.001 0.001 0.001</scale>
            <uri>model://meshes/adafruit_bno055_stemma_qt_1.stl</uri>
          </mesh>
        </geometry>
      </visual>
      <visual name='base_footprint_fixed_joint_lump__laser_visual_4'>
        <pose>0 0 0.1955 0 -0 0</pose>
        <geometry>
          <mesh>
            <scale>0.001 0.001 0.001</scale>
            <uri>model://meshes/c1m1_appearance_v2_20230926_3d_.stl</uri>
          </mesh>
        </geometry>
      </visual>
      <visual name='base_footprint_fixed_joint_lump__rear_caster_wheel_link_visual_5'>
        <pose>-0.0485 0.0065 0.01267 0 0 -1.5708</pose>
        <geometry>
          <mesh>
            <scale>0.001 0.001 0.001</scale>
            <uri>model://meshes/caster_wheel.stl</uri>
          </mesh>
        </geometry>
        <material>
          <script>
            <name>Gazebo/FlatBlack</name>
            <uri>file://media/materials/scripts/gazebo.material</uri>
          </script>
        </material>
      </visual>
      <sensor name='camera' type='camera'>
        <visualize>1</visualize>
        <update_rate>30</update_rate>
        <camera>
          <horizontal_fov>1.0856</horizontal_fov>
          <image>
            <width>640</width>
            <height>480</height>
            <format>R8G8B8</format>
          </image>
          <clip>
            <near>0.05</near>
            <far>3</far>
          </clip>
        </camera>
        <plugin name='camera_controller' filename='libgazebo_ros_camera.so'>
          <alwaysOn>1</alwaysOn>
          <imageTopicName>image_raw/compressed</imageTopicName>
          <frame_name>camera_optical</frame_name>
        </plugin>
        <pose>0.07 0 0.159 0 -0 0</pose>
      </sensor>
      <m1 value='10.0'/>
      <m2 value='10.0'/>
      <m1 value='10.0'/>
      <m2 value='10.0'/>
    </link>
    <joint name='base_left_wheel_joint' type='revolute'>
      <pose relative_to='base_footprint'>0 0.0775 0.033 1.5708 0 0</pose>
      <parent>base_footprint</parent>
      <child>left_wheel_link</child>
      <axis>
        <xyz>0 0 -1</xyz>
        <limit>
          <lower>-1e+16</lower>
          <upper>1e+16</upper>
        </limit>
        <dynamics>
          <spring_reference>0</spring_reference>
          <spring_stiffness>0</spring_stiffness>
        </dynamics>
      </axis>
    </joint>
    <link name='left_wheel_link'>
      <pose relative_to='base_left_wheel_joint'>0 0 0 0 -0 0</pose>
      <inertial>
        <pose>0 0 0 0 -0 0</pose>
        <mass>500</mass>
        <inertia>
          <ixx>0.162167</ixx>
          <ixy>0</ixy>
          <ixz>0</ixz>
          <iyy>0.162167</iyy>
          <iyz>0</iyz>
          <izz>0.27225</izz>
        </inertia>
      </inertial>
      <collision name='left_wheel_link_collision'>
        <pose>0 0 0 0 -0 0</pose>
        <geometry>
          <sphere>
            <radius>0.033</radius>
          </sphere>
        </geometry>
        <surface>
          <contact>
            <ode/>
          </contact>
          <friction>
            <ode/>
          </friction>
        </surface>
      </collision>
      <visual name='left_wheel_link_visual'>
        <pose>0 0 -0.0125 1.5708 -0 0</pose>
        <geometry>
          <mesh>
            <scale>0.001 0.001 0.001</scale>
            <uri>model://meshes/wheel.stl</uri>
          </mesh>
        </geometry>
        <material>
          <script>
            <name>Gazebo/Orange</name>
            <uri>file://media/materials/scripts/gazebo.material</uri>
          </script>
        </material>
      </visual>
      <m1 value='10.0'/>
      <m2 value='10.0'/>
    </link>
    <joint name='base_right_wheel_joint' type='revolute'>
      <pose relative_to='base_footprint'>0 -0.0775 0.033 -1.5708 0 0</pose>
      <parent>base_footprint</parent>
      <child>right_wheel_link</child>
      <axis>
        <xyz>0 0 1</xyz>
        <limit>
          <lower>-1e+16</lower>
          <upper>1e+16</upper>
        </limit>
        <dynamics>
          <spring_reference>0</spring_reference>
          <spring_stiffness>0</spring_stiffness>
        </dynamics>
      </axis>
    </joint>
    <link name='right_wheel_link'>
      <pose relative_to='base_right_wheel_joint'>0 0 0 0 -0 0</pose>
      <inertial>
        <pose>0 0 0 0 -0 0</pose>
        <mass>500</mass>
        <inertia>
          <ixx>0.162167</ixx>
          <ixy>0</ixy>
          <ixz>0</ixz>
          <iyy>0.162167</iyy>
          <iyz>0</iyz>
          <izz>0.27225</izz>
        </inertia>
      </inertial>
      <collision name='right_wheel_link_collision'>
        <pose>0 0 0 0 -0 0</pose>
        <geometry>
          <sphere>
            <radius>0.033</radius>
          </sphere>
        </geometry>
        <surface>
          <contact>
            <ode/>
          </contact>
          <friction>
            <ode/>
          </friction>
        </surface>
      </collision>
      <visual name='right_wheel_link_visual'>
        <pose>0 0 -0.0125 1.5708 -0 0</pose>
        <geometry>
          <mesh>
            <scale>0.001 0.001 0.001</scale>
            <uri>model://meshes/wheel.stl</uri>
          </mesh>
        </geometry>
        <material>
          <script>
            <name>Gazebo/Orange</name>
            <uri>file://media/materials/scripts/gazebo.material</uri>
          </script>
        </material>
      </visual>
      <m1 value='10.0'/>
      <m2 value='10.0'/>
    </link>

    
    <plugin name="diff_drive_controller" filename="libgazebo_ros_diff_drive.so"> 
      <ros>
        <namespace>/my_robot</namespace>
        <remapping>cmd_vel:=/cmd_vel_out</remapping>
        <remapping>odom:=/odom</remapping>
      </ros>
      <robotNamespace>/my_robot</robotNamespace>
      <left_joint>base_left_wheel_joint</left_joint>
      <right_joint>base_right_wheel_joint</right_joint>
      <wheel_separation>0.155</wheel_separation>
      <wheel_diameter>0.066</wheel_diameter>
      <update_rate>100.0</update_rate>
      <max_velocity>1.0</max_velocity>
    </plugin>
  
  
    <plugin name="joint_state_publisher" filename="libgazebo_ros_joint_state_publisher.so">
        <namespace>/my_robot</namespace>
        <joint_name>base_left_wheel_joint</joint_name>
        <joint_name>base_right_wheel_joint</joint_name>
        <remapping>joint_states:=/joint_states</remapping>
        <joint_state_source>sensor</joint_state_source>
        <update_rate>100.0</update_rate>
        <alwaysOn>true</alwaysOn>
    </plugin>


  </model>
</sdf>
