<?xml version="1.0" ?>
<!-- =================================================================================== -->
<!-- |    This document was autogenerated by xacro from my_robot_base_mesh_copy.xacro  | -->
<!-- |    EDITING THIS FILE BY HAND IS NOT RECOMMENDED                                 | -->
<!-- =================================================================================== -->
<robot name= "my_robot">
  <material name="orange">
    <color rgba="1 0.647 0.0 1"/>
  </material>
  <material name="grey">
    <color rgba="0.5 0.5 0.5 1"/>
  </material>
  <material name="white">
    <color rgba="1 1 1 1"/>
  </material>
  <material name="red">
    <color rgba="1 0.0 0.0 1"/>
  </material>
  <material name="black">
    <color rgba="0.0 0.0 0.0 1"/>
  </material>
  <material name="green">
    <color rgba="0.0 0.1 0.0 1"/>
  </material>
  <material name="grünlichesGrau">
    <color rgba="0.6 0.7 0.6 1"/>
  </material>
  <material name="warmesRot">
    <color rgba="0.8 0.1 0.1 1"/>
  </material>
  <material name="grauBlau">
    <color rgba="0.4 0.5 0.6 1"/>
  </material>
  <material name="pastelligesZitronengelb">
    <color rgba="1.0 1.0 0.6 1"/>
  </material>
  <gazebo reference="base_link">
    <material>Gazebo/DarkGrey</material>
  </gazebo>
  <gazebo reference="right_wheel_link">
    <material>Gazebo/Orange</material>
    <m1 value="10.0"/>
    <m2 value="10.0"/>
  </gazebo>
  <gazebo reference="left_wheel_link">
    <material>Gazebo/Orange</material>
    <m1 value="10.0"/>
    <m2 value="10.0"/>
  </gazebo>
  <gazebo reference="front_caster_wheel_link">
    <material>Gazebo/FlatBlack</material>
    <m1 value="10.0"/>
    <m2 value="10.0"/>
  </gazebo>
  <gazebo reference="rear_caster_wheel_link">
    <material>Gazebo/FlatBlack</material>
    <m1 value="10.0"/>
    <m2 value="10.0"/>
  </gazebo>
  <!-- base_footprint -->
  <link name="base_footprint"/>
  <!-- base_link -->
  <link name="base_link">
    <visual>
      <geometry>
        <mesh filename="package://my_robot_description/models/meshes/my_robot_base.stl" scale="0.001 0.001 0.001"/>
      </geometry>
      <material name="grünlichesGrau"/>
      <origin rpy="1.5707963267948966 0.0 1.5707963267948966" xyz="0.0 0.0 0.1375"/>
    </visual>
    <collision>
      <geometry>
        <cylinder length="0.1855" radius="0.07"/>
      </geometry>
      <origin rpy="0.0 0.0 0.0" xyz="0.0 0.0 0.09275"/>
    </collision>
    <inertial>
      <origin rpy="0.0 0.0 0.0" xyz="0.0 0.0 0.09325"/>
      <mass value="1000.0"/>
      <inertia ixx="4.500854166666666" ixy="0.0" ixz="0.0" iyy="4.500854166666666" iyz="0.0" izz="3.266666666666667"/>
    </inertial>
  </link>
  <!-- footprint_base_joint -->
  <joint name="footprint_base_joint" type="fixed">
    <parent link="base_footprint"/>
    <child link="base_link"/>
    <origin rpy="0 0 0" xyz="0 0 0.0125"/>
  </joint>
  <link name="right_wheel_link">
    <visual>
      <geometry>
        <mesh filename="package://my_robot_description/models/meshes/wheel.stl" scale="0.001 0.001 0.001"/>
      </geometry>
      <material name="grauBlau"/>
      <origin rpy="1.5707963267948966  0.0 0.0" xyz="0.0 0.0 -0.0125"/>
    </visual>
    <collision>
      <geometry>
        <sphere radius="0.033"/>
      </geometry>
      <origin rpy="0.0 0.0 0.0" xyz="0.0 0.0 0.0"/>
    </collision>
    <inertial>
      <origin rpy="0.0 0.0 0.0" xyz="0.0 0.0 0.0"/>
      <mass value="500.0"/>
      <inertia ixx="0.16216666666666668" ixy="0.0" ixz="0.0" iyx="0.0" iyy="0.16216666666666668" iyz="0.0" izx="0.0" izy="0.0" izz="0.27225000000000005"/>
    </inertial>
  </link>
  <link name="left_wheel_link">
    <visual>
      <geometry>
        <mesh filename="package://my_robot_description/models/meshes/wheel.stl" scale="0.001 0.001 0.001"/>
      </geometry>
      <material name="grauBlau"/>
      <origin rpy="1.5707963267948966  0.0 0.0" xyz="0.0 0.0 -0.0125"/>
    </visual>
    <collision>
      <geometry>
        <sphere radius="0.033"/>
      </geometry>
      <origin rpy="0.0 0.0 0.0" xyz="0.0 0.0 0.0"/>
    </collision>
    <inertial>
      <origin rpy="0.0 0.0 0.0" xyz="0.0 0.0 0.0"/>
      <mass value="500.0"/>
      <inertia ixx="0.16216666666666668" ixy="0.0" ixz="0.0" iyx="0.0" iyy="0.16216666666666668" iyz="0.0" izx="0.0" izy="0.0" izz="0.27225000000000005"/>
    </inertial>
  </link>
  <!-- base_left_wheel_joint -->
  <joint name="base_left_wheel_joint" type="continuous">
    <parent link="base_link"/>
    <child link="left_wheel_link"/>
    <origin rpy="-1.5707963267948966 3.141592653589793 3.141592653589793" xyz="0.0 0.0775 0.0205"/>
    <axis xyz="0 0 -1"/>
  </joint>
  <!-- base_right_wheel_joint -->
  <joint name="base_right_wheel_joint" type="continuous">
    <parent link="base_link"/>
    <child link="right_wheel_link"/>
    <origin rpy="-1.5707963267948966 0.0 0.0" xyz="0.0 -0.0775 0.0205"/>
    <axis xyz="0 0 1"/>
  </joint>
  <link name="front_caster_wheel_link">
    <visual>
      <geometry>
        <mesh filename="package://my_robot_description/models/meshes/caster_wheel.stl" scale="0.001 0.001 0.001"/>
      </geometry>
      <material name="black"/>
      <origin rpy="0.0 0.0 -1.5707963267948966" xyz="0.0 0.0065 0.0"/>
    </visual>
    <collision>
      <geometry>
        <sphere radius="0.0125"/>
      </geometry>
      <material name="black"/>
      <origin rpy="0.0 0.0 0.0" xyz="0.0 0.0 0.0"/>
    </collision>
    <inertial>
      <origin rpy="0.0 0.0 0.0" xyz="0.0 0.0 0.0"/>
      <mass value="250.0"/>
      <inertia ixx="0.013286458333333334" ixy="0.0" ixz="0.0" iyx="0.0" iyy="0.013286458333333334" iyz="0.0" izx="0.0" izy="0.0" izz="0.019531250000000003"/>
    </inertial>
  </link>
  <link name="rear_caster_wheel_link">
    <visual>
      <geometry>
        <mesh filename="package://my_robot_description/models/meshes/caster_wheel.stl" scale="0.001 0.001 0.001"/>
      </geometry>
      <material name="black"/>
      <origin rpy="0.0 0.0 -1.5707963267948966" xyz="0.0 0.0065 0.0"/>
    </visual>
    <collision>
      <geometry>
        <sphere radius="0.0125"/>
      </geometry>
      <material name="black"/>
      <origin rpy="0.0 0.0 0.0" xyz="0.0 0.0 0.0"/>
    </collision>
    <inertial>
      <origin rpy="0.0 0.0 0.0" xyz="0.0 0.0 0.0"/>
      <mass value="250.0"/>
      <inertia ixx="0.013286458333333334" ixy="0.0" ixz="0.0" iyx="0.0" iyy="0.013286458333333334" iyz="0.0" izx="0.0" izy="0.0" izz="0.019531250000000003"/>
    </inertial>
  </link>
  <!--base_front_caster_wheel_joint-->
  <joint name="base_front_caster_wheel_joint" type="fixed">
    <parent link="base_link"/>
    <child link="front_caster_wheel_link"/>
    <origin rpy="0.0 0.0 0.0" xyz="0.0485 0.0 0.00017"/>
  </joint>
  <!--base_rear_caster_wheel_joint-->
  <joint name="base_rear_caster_wheel_joint" type="fixed">
    <parent link="base_link"/>
    <child link="rear_caster_wheel_link"/>
    <origin rpy="0.0 0.0 0.0" xyz="-0.0485 0.0 0.00017"/>
  </joint>
  <!-- lidar_link -->
  <link name="laser">
    <visual>
      <geometry>
        <mesh filename="package://my_robot_description/models/meshes/c1m1_appearance_v2_20230926_3d_.stl" scale="0.001 0.001 0.001"/>
      </geometry>
      <material name="pastelligesZitronengelb"/>
      <origin rpy="0.0 0.0 0.0" xyz="0.0 0.0 0.0"/>
    </visual>
    <collision>
      <geometry>
        <cylinder length="0.0413" radius="0.0348"/>
      </geometry>
      <origin rpy="0.0 0.0 0.0" xyz="0.0 0.0 0.02065"/>
    </collision>
    <inertial>
      <origin rpy="0.0 0.0 0.0" xyz="0.0 0.0 0.02065"/>
      <mass value="0.1"/>
      <inertia ixx="3.219175e-05" ixy="0.0" ixz="0.0" iyx="0.0" iyy="3.219175e-05" iyz="0.0" izx="0.0" izy="0.0" izz="3.8642e-05"/>
    </inertial>
  </link>
  <!-- base_laser_joint -->
  <joint name="base_laser_joint" type="fixed">
    <parent link="base_link"/>
    <child link="laser"/>
    <origin rpy="0 0 0" xyz="0 0 0.183"/>
  </joint>
  <!-- imu_link -->
  <link name="bno055">
    <visual>
      <geometry>
        <mesh filename="package://my_robot_description/models/meshes/adafruit_bno055_stemma_qt_1.stl" scale="0.001 0.001 0.001"/>
      </geometry>
      <material name="warmesRot"/>
      <origin rpy="0.0 0.0 0.0" xyz="0.0 0.0 0.00075"/>
    </visual>
    <collision>
      <geometry>
        <box size="0.02 0.025 0.0045000000000000005"/>
      </geometry>
      <origin rpy="0.0 0.0 1.5707963267948966" xyz="0.0 0.0 0.003"/>
    </collision>
    <inertial>
      <origin rpy="0.0 0.0 0.0" xyz="0.0 0.0 0.00075"/>
      <mass value="0.05"/>
      <inertia ixx="2.6135416666666672e-06" ixy="0.0" ixz="0.0" iyy="4.270833333333333e-06" iyz="0.0" izz="1.6760416666666667e-06"/>
    </inertial>
  </link>
  <!-- base_imu_joint -->
  <joint name="base_imu_joint" type="fixed">
    <parent link="base_link"/>
    <child link="bno055"/>
    <origin rpy="0 0 0.0" xyz="0 0 0.17300000000000001"/>
  </joint>
</robot>
